Workbook

Sheet Inputs
A1: Inputs and Assumptions
C2: Source(given or asumed)
A3: Total feed, F (kmol/h) | B3: 100 | C3: Given in the project statement as 100 kmol/h total feed to the downstream separation section.
A4: MeOH feed mole fraction | B4: 0.1292 | C4: Given in the Group 20 feed composition as 12.92 mol% methanol.
A5: Water feed mole fraction | B5: 0.6118 | C5: Given in the Group 20 feed composition as 61.18 mol% water.
A6: Glycerol feed mole fraction | B6: 0.259 | C6: Given in the Group 20 feed composition as 25.90 mol% glycerol.
A7: Minimum MeOH product purity | B7: 0.95 | C7: Given in the project specification. Methanol product must reach at least 95 mol% purity.
A8: Minimum water product purity | B8: 0.95 | C8: Given in the project specification. Water product must reach at least 95 mol% purity.
A9: Minimum glycerol product purity | B9: 0.95 | C9: Given in the project specification. Glycerol product must reach at least 95 mol% purity.
A10: Operating hours (h/year) | B10: 8000 | C10: Assumed annual operating time for preliminary utility and annual cost calculations.
A12: Component | B12: Formula | C12: MW (kg/kmol) | D12: Cp_liq (kJ/mol-K) | E12: Hvap (kJ/mol) | F12: rho_liq ref (kg/m3) | G12: Role | H12: Notes
A13: Methanol | B13: CH4O | C13: 32.0419 | D13: 0.081 | E13: 35.3 | F13: 792 | G13: Light key | H13: NIST Chemistry WebBook
A14: Water | B14: H2O | C14: 18.0153 | D14: 0.0753 | E14: 40.7 | F14: 958 | G14: Heavy key | H14: NIST Chemistry WebBook
A15: Glycerol | B15: C3H8O3 | C15: 92.0938 | D15: 0.24 | E15: 0 | F15: 1260 | G15: Heavy nonvolatile | H15: NIST Chemistry WebBook
A17: Constant set | B17: Component | C17: T range/usage | D17: A | E17: B | F17: C | G17: Equation | H17: Source
A18: Flash 1 | B18: Methanol | C18: 90 degC | D18: 5.15853 | E18: 1569.613 | F18: -34.846 | G18: log10(Pbar)=A-B/(T_K+C) | H18: NIST Chemistry WebBook
A19: Flash 1 | B19: Water | C19: 90 degC | D19: 5.0768 | E19: 1659.793 | F19: -45.854 | G19: log10(Pbar)=A-B/(T_K+C) | H19: NIST Chemistry WebBook
A20: Flash 2 | B20: Methanol | C20: 120 degC | D20: 5.15853 | E20: 1569.613 | F20: -34.846 | G20: log10(Pbar)=A-B/(T_K+C) | H20: NIST Chemistry WebBook
A21: Flash 2 | B21: Water | C21: 120 degC; NIST high-temperature range | D21: 3.55959 | E21: 643.748 | F21: -198.043 | G21: log10(Pbar)=A-B/(T_K+C) | H21: NIST Chemistry WebBook
C22: Source(selected ones)
A23: Flash 1 T (degC) | B23: 90 | C23: Selected design temperature for Flash 1 to vaporize a significant fraction of methanol and water while keeping glycerol mostly in the liquid phase. | D23: Hydraulic assumptions | E23: Value | F23: Unit | G23: Basis
A24: Flash 1 P (bar abs) | B24: 0.5 | C24: Selected reduced pressure for Flash 1 to increase methanol and water volatility and improve vapor recovery. | D24: rho_G | E24: 0.6 | F24: kg/m3 | G24: Bottom vapor, preliminary
A25: Flash 1 vapor fraction beta | B25: 0.37611681 | C25: Calculated from the Rachford–Rice flash equation. Beta is adjusted until the flash residual becomes approximately zero. | D25: rho_L | E25: 950 | F25: kg/m3 | G25: Bottom liquid, preliminary
A26: Flash 2 T (degC) | B26: 120 | C26: Selected design temperature for Flash 2 to remove additional methanol and water from the glycerol-rich liquid stream. | D26: surface tension | E26: 0.055 | F26: N/m | G26: Methanol-water at column bottom, screening
A27: Flash 2 P (bar abs) | B27: 0.08 | C27: Selected low pressure for Flash 2 to vaporize water and methanol at a lower temperature and concentrate glycerol in the liquid product. | D27: K1 chart | E27: 0.06 | F27: m/s | G27: Read from course capacity chart
A28: Flash 2 vapor fraction beta | B28: 0.56706739 | C28: Calculated from the Rachford–Rice flash equation using the corrected Flash 2 water Antoine constants. | D28: Flooding design fraction | E28: 0.7 | F28: - | G28: Used for diameter sizing
A29: Column pressure (bar abs) | B29: 1.013 | C29: Selected as atmospheric pressure for preliminary distillation column design. | D29: Plate spacing | E29: 0.45 | F29: m | G29: Course guideline for Dc < 1.2 m
A30: Relative volatility alpha_MeOH/H2O | B30: 4.5 | C30: Assumed constant relative volatility for preliminary methanol–water distillation calculations. | D30: Pre-column condenser outlet T | E30: 40 | F30: degC | G30: Screening assumption for fully condensed S6 before pumping
A31: Reflux ratio multiplier R/Rmin | B31: 1.2 | C31: Selected after sensitivity analysis. A value of 1.20 gives the lowest preliminary total annualized cost among the tested cases. | D31: Column feed T for q=1 | E31: 85 | F31: degC | G31: Estimated saturated-liquid feed temperature at 1.013 bar
A32: Overall tray efficiency | B32: 0.7 | C32: Assumed overall tray efficiency for converting theoretical stages into actual trays in preliminary sieve-plate column design. | D32: Liquid pump efficiency | E32: 0.7 | F32: - | G32: Screening assumption

Sheet Feed
A1: Feed Balance: Group 20
A3: Component | B3: z_i | C3: F_i (kmol/h) | D3: MW (kg/kmol) | E3: Mass flow (kg/h) | F3: Mass fraction
A4: Methanol | B4: 0.1292 | C4: =Inputs!$B$3*B4 -> 12.92 | D4: 32.0419 | E4: =C4*D4 -> 413.98135 | F4: =E4/SUM($E$4:$E$6) -> 0.10611133
A5: Water | B5: 0.6118 | C5: =Inputs!$B$3*B5 -> 61.18 | D5: 18.0153 | E5: =C5*D5 -> 1102.1761 | F5: =E5/SUM($E$4:$E$6) -> 0.28250879
A6: Glycerol | B6: 0.259 | C6: =Inputs!$B$3*B6 -> 25.9 | D6: 92.0938 | E6: =C6*D6 -> 2385.2294 | F6: =E6/SUM($E$4:$E$6) -> 0.61137988
A8: Total | B8: =SUM(B4:B6) -> 1 | C8: =SUM(C4:C6) -> 100 | E8: =SUM(E4:E6) -> 3901.3868 | F8: =SUM(F4:F6) -> 1

Sheet Flash
A1: Two-Flash Separation Calculations
A3: Flash 1 feed F (kmol/h) | B3: 100
A4: Flash 1 T (degC) | B4: 90
A5: Flash 1 P (bar) | B5: 0.5
A6: Flash 1 beta = V/F | B6: 0.37611681
A7: RR residual | B7: =SUMPRODUCT(B10:B12,C10:C12-1,1/(1+$B$6*(C10:C12-1))) -> 1.110223e-16
A9: Component | B9: z_i | C9: K_i | D9: x_i | E9: y_i | F9: V_i (kmol/h) | G9: L_i (kmol/h) | H9: V_i/F_i | I9: L_i/F_i | J9: Note
A10: Methanol | B10: 0.1292 | C10: =10^(5.15853-1569.613/(($B$4+273.15)-34.846))/$B$5 -> 4.770739 | D10: =B10/(1+$B$6*(C10-1)) -> 0.053427323 | E10: =C10*D10 -> 0.25488781 | F10: =$B$3*$B$6*E10 -> 9.5867592 | G10: =$B$3*(1-$B$6)*D10 -> 3.3332408 | H10: =F10/(F10+G10) -> 0.74200922 | I10: =G10/(F10+G10) -> 0.25799078 | J10: K from Antoine
A11: Water | B11: 0.6118 | C11: =10^(5.0768-1659.793/(($B$4+273.15)-45.854))/$B$5 -> 1.4020853 | D11: =B11/(1+$B$6*(C11-1)) -> 0.53143111 | E11: =C11*D11 -> 0.74511177 | F11: =$B$3*$B$6*E11 -> 28.024907 | G11: =$B$3*(1-$B$6)*D11 -> 33.155093 | H11: =F11/(F11+G11) -> 0.45807301 | I11: =G11/(F11+G11) -> 0.54192699 | J11: K from Antoine
A12: Glycerol | B12: 0.259 | C12: 1e-06 | D12: =B12/(1+$B$6*(C12-1)) -> 0.41514157 | E12: =C12*D12 -> 4.1514157e-07 | F12: =$B$3*$B$6*E12 -> 1.5614172e-05 | G12: =$B$3*(1-$B$6)*D12 -> 25.899984 | H12: =F12/(F12+G12) -> 6.028638e-07 | I12: =G12/(F12+G12) -> 0.9999994 | J12: Nonvolatile K
A14: Totals | D14: =SUM(D10:D12) -> 1 | E14: =SUM(E10:E12) -> 1 | F14: =SUM(F10:F12) -> 37.611681 | G14: =SUM(G10:G12) -> 62.388319
A17: Flash 2 feed F (kmol/h) | B17: =G14 -> 62.388319
A18: Flash 2 T (degC) | B18: 120
A19: Flash 2 P (bar) | B19: 0.08
A20: Flash 2 beta = V/F | B20: 0.56706739
A21: RR residual | B21: =SUMPRODUCT(B25:B27,C25:C27-1,1/(1+$B$20*(C25:C27-1))) -> -1.110223e-16
A22: Final glycerol purity | B22: =G27/G29 -> 0.95890449
A24: Component | B24: z_i | C24: K_i | D24: x_i | E24: y_i | F24: V_i (kmol/h) | G24: L_i (kmol/h) | H24: V_i/F_i | I24: L_i/F_i | J24: Note
A25: Methanol | B25: =G10/$B$17 -> 0.053427323 | C25: =10^(5.15853-1569.613/(($B$18+273.15)-34.846))/$B$19 -> 74.949038 | D25: =B25/(1+$B$20*(C25-1)) -> 0.0012444034 | E25: =C25*D25 -> 0.093266834 | F25: =$B$17*$B$20*E25 -> 3.2996296 | G25: =$B$17*(1-$B$20)*D25 -> 0.033611257 | H25: =F25/(F25+G25) -> 0.98991634 | I25: =G25/(F25+G25) -> 0.010083657 | J25: K from Antoine
A26: Water | B26: =G11/$B$17 -> 0.53143111 | C26: =10^(3.55959-643.748/(($B$18+273.15)-198.043))/$B$19 -> 22.753001 | D26: =B26/(1+$B$20*(C26-1)) -> 0.039851103 | E26: =C26*D26 -> 0.90673221 | F26: =$B$17*$B$20*E26 -> 32.078718 | G26: =$B$17*(1-$B$20)*D26 -> 1.0763758 | H26: =F26/(F26+G26) -> 0.96753513 | I26: =G26/(F26+G26) -> 0.03246487 | J26: K from NIST high-temperature Antoine set
A27: Glycerol | B27: =G12/$B$17 -> 0.41514157 | C27: 1e-06 | D27: =B27/(1+$B$20*(C27-1)) -> 0.95890449 | E27: =C27*D27 -> 9.5890449e-07 | F27: =$B$17*$B$20*E27 -> 3.3924489e-05 | G27: =$B$17*(1-$B$20)*D27 -> 25.89995 | H27: =F27/(F27+G27) -> 1.3098266e-06 | I27: =G27/(F27+G27) -> 0.99999869 | J27: Nonvolatile K
A29: Totals | D29: =SUM(D25:D27) -> 1 | E29: =SUM(E25:E27) -> 1 | F29: =SUM(F25:F27) -> 35.378381 | G29: =SUM(G25:G27) -> 27.009938

Sheet Column
A1: Continuous Multistage Distillation Column Design
A3: Component | B3: Column feed kmol/h | C3: z_i | D3: Distillate kmol/h | E3: x_D | F3: Bottoms kmol/h | G3: x_B | H3: Feed source | I3: Product role | J3: Recovery basis
A4: Methanol | B4: =Flash!F10+Flash!F25 -> 12.886389 | C4: =B4/SUM($B$4:$B$6) -> 0.17654991 | D4: =$B$9*$B$15 -> 12.587689 | E4: =D4/$B$15 -> 0.95 | F4: =B4-D4 -> 0.29869932 | G4: =F4/$B$16 -> 0.005 | H4: Flash 1 vapor + Flash 2 vapor | I4: Methanol product | J4: =D4/Feed!C4 -> 0.97427937
A5: Water | B5: =Flash!F11+Flash!F26 -> 60.103624 | C5: =B5/SUM($B$4:$B$6) -> 0.82344941 | D5: =(1-$B$9)*$B$15 -> 0.66250997 | E5: =D5/$B$15 -> 0.05 | F5: =B5-D5 -> 59.441114 | G5: =F5/$B$16 -> 0.99499917 | H5: Flash 1 vapor + Flash 2 vapor | I5: Water product | J5: =F5/Feed!C5 -> 0.97157755
A6: Glycerol | B6: =Flash!F12+Flash!F27 -> 4.9538661e-05 | C6: =B6/SUM($B$4:$B$6) -> 6.7870419e-07 | D6: 0 | E6: =D6/$B$15 -> 0 | F6: =B6-D6 -> 4.9538661e-05 | G6: =F6/$B$16 -> 8.2923961e-07 | H6: Trace only | I6: Trace in bottoms | J6: =Flash!G27/Feed!C6 -> 0.99999809
A9: MeOH distillate purity xD | B9: 0.95
A10: MeOH bottoms mole fraction xB | B10: 0.005
A11: Relative volatility alpha | B11: 4.5 | C11: A constant relative volatility of 4.5 was assumed for the preliminary methanol-water column design. This is a simplifying assumption, a rigorous final design should use experimental VLE data or an activity coefficient model.
A12: q-value | B12: 1 | C12: Assumption: S2 and S4 leave the flash drums as vapor, are fully condensed/mixed, pumped to 1.013 bar, and heated to the column bubble-point condition. Therefore S6 enters as saturated liquid and q = 1.
A13: R/Rmin selected | B13: 1.2 | C13: design choice
A14: Tray efficiency | B14: 0.7 | C14: An overall tray efficiency of 70% was assumed for preliminary design. This means that actual trays are less efficient than ideal theoretical stages. Therefore, the number of actual trays was calculated by dividing the theoretical stages by 0.70.
A15: Distillate total D (kmol/h) | B15: =(B4-$B$10*SUM($B$4:$B$6))/($B$9-$B$10) -> 13.250199
A16: Bottoms total B (kmol/h) | B16: =SUM($B$4:$B$6)-$B$15 -> 59.739863
A17: yF equilibrium at zF | B17: =$B$11*C4/(1+($B$11-1)*C4) -> 0.49104547 | C17: yF* = equilibrium vapor composition at xF on the VLE curve; it is used for Rmin and is not the actual feed vapor composition.
A18: Rmin | B18: =($B$9-$B$17)/($B$17-C4) -> 1.4593355
A19: R selected | B19: =$B$13*$B$18 -> 1.7512026
A20: Vapor boilup V=(R+1)D | B20: =($B$19+1)*$B$15 -> 36.453983
A22: Totals | B22: =SUM(B4:B6) -> 72.990062 | D22: =SUM(D4:D6) -> 13.250199 | F22: =SUM(F4:F6) -> 59.739863
A24: Minimum stages, Nmin | B24: =LN(($B$9/$B$10)*(G5/E5))/LN($B$11) -> 5.4769409 | C24: Fenske equation
A25: Gilliland X | B25: =($B$19-$B$18)/($B$19+1) -> 0.1060871
A26: Gilliland Y | B26: =1-EXP(((1+54.4*B25)/(11+117.2*B25))*(B25-1)/SQRT(B25)) -> 0.54752871
A27: Theoretical stages | B27: =(B24+B26)/(1-B26) -> 13.31459
A28: Rounded theoretical stages | B28: =CEILING(B27,1) -> 14
A29: Actual trays | B29: =CEILING(B28/$B$14,1) -> 20
A30: Estimated feed tray from top | B30: =CEILING(B29*0.55,1) -> 11
A31: Column diameter selected (m) | B31: =Hydraulics_TopBottom!B22 -> 0.7
A32: Tray spacing (m) | B32: 0.45
A33: Approx. tangent-to-tangent height (m) | B33: =2.5+B29*B32 -> 11.5

Sheet Hydraulics
A1: Sieve-Plate Column Hydraulic Design
A3: Parameter | B3: Value | C3: Unit | F3: Parameter | G3: Value | H3: Unit | I3: Criterion
A4: Vapor mass flow Gdot | B4: 0.18556566 | C4: kg/s | F4: Downcomer area fraction a | G4: 0.0945 | H4: - | I4: Lw/Dc=0.715 -> a=0.0945
A5: Liquid mass flow Ldot | B5: 0.48325204 | C5: kg/s | F5: Active area Aa | G5: 0.31210938 | H5: m2 | I5: Aa=Ac-2Ad
A6: rho_G | B6: 0.6 | C6: kg/m3 | F6: Hole area Ah | G6: 0.015605469 | H6: m2 | I6: Ah/Aa=0.05 within 0.05-0.15
A7: rho_L | B7: 950 | C7: kg/m3 | F7: Number of holes | G7: 795 | H7: holes | I7: dh=5 mm
A8: Surface tension sigma | B8: 0.055 | C8: N/m | F8: Hole pitch | G8: 21.295539 | H8: mm | I8: 2.5-5 dh
A9: Flow parameter FLG | B9: =B5/B4*SQRT(B6/B7) -> 0.065447024 | C9: - | F9: Weir length Lw | G9: 0.5005 | H9: m | I9: Lw/Dc=0.715
A10: K1 chart | B10: 0.06 | C10: m/s | F10: Weir crest how | G10: 7.5815605 | H10: mm | I10: hw+how > 50 mm
A11: K1 corrected | B11: =B10*(B8/0.02)^0.2 -> 0.073454396 | C11: m/s | F11: Hole velocity uh | G11: 19.818444 | H11: m/s | I11: uh > uhm
A12: Flooding velocity uGF | B12: =B11*SQRT((B7-B6)/B6) -> 2.9219096 | C12: m/s | F12: Minimum hole velocity uhm | G12: 15.414474 | H12: m/s | I12: weeping limit
A13: Design flooding fraction | B13: 0.7 | C13: - | F13: Dry pressure drop ho | G13: 20.794463 | H13: mm liq | I13: screening
A14: Required diameter | B14: =SQRT(4*B4/(PI()*B6*(B13*B12)*(1-0.0945))) -> 0.46110688 | C14: m | F14: Aerated liquid drop ha | G14: 35.700567 | H14: mm liq | I14: screening
A15: Selected diameter | B15: =Column!B31 -> 0.7 | C15: m | F15: Total gas pressure drop hT | G15: 56.49503 | H15: mm liq | I15: screening
A16: Actual flooding percent | B16: 0.30374223 | C16: - | F16: Downcomer backup hda | G16: 185.7 | H16: mm | I16: hda <= 0.5*PS*1000 = 225 mm
F17: Downcomer residence time | G17: 32.172158 | H17: s | I17: > 5 s
F18: Estimated entrainment E | G18: 0.012 | H18: - | I18: < 0.1

Sheet Energy_Cost
A1: Energy Balance and Preliminary Cost Model
A3: Items | B3: Sensible (kW) | C3: Latent/Condensing (kW) | D3: Total duty / power (kW) | E3: Equation / Basis | F3: Cost treatment
A4: Flash 1 heater | B4: =Feed!C8*(SUMPRODUCT(Feed!B4:B6,Inputs!D13:D15))*(Inputs!B23-25)/3.6 -> 214.30814 | C4: =Flash!F14*(Flash!F10/Flash!F14*Inputs!E13+Flash!F11/Flash!F14*Inputs!E14)/3.6 -> 410.84064 | D4: =B4+C4 -> 625.14878 | E4: Sensible feed heating from 25 C to 90 C + vaporization | F4: Duty only; excluded from TAC
A5: Flash 2 heater | B5: =Flash!G14*(SUMPRODUCT(Flash!D10:D12,Inputs!D13:D15))*(Inputs!B26-Inputs!B23)/3.6 -> 74.854727 | C5: =Flash!F29*(Flash!F25/Flash!F29*Inputs!E13+Flash!F26/Flash!F29*Inputs!E14)/3.6 -> 395.02243 | D5: =B5+C5 -> 469.87715 | E5: Liquid heating from 90 C to 120 C + vaporization | F5: Duty only; excluded from TAC
A6: Column reboiler | B6: 0 | C6: =Column!B20*(Column!G5*Inputs!E14+Column!G4*Inputs!E13)/3.6 -> 411.85878 | D6: =B6+C6 -> 411.85878 | E6: V=(R+1)D times latent heat of water-rich vapor | F6: Included in TAC
A7: Column condenser | B7: 0 | C7: =Column!B20*(Column!E4*Inputs!E13+Column!E5*Inputs!E14)/3.6 -> 360.1856 | D7: =B7+C7 -> 360.1856 | E7: Top vapor condensation, methanol-rich | F7: Included in TAC
A8: Column feed heater | B8: =Column!B22*SUMPRODUCT(Column!C4:C6,Inputs!D13:D15)*(Inputs!E31-Inputs!E30)/3.6 -> 69.620153 | C8: 0 | D8: =B8+C8 -> 69.620153 | E8: Heat condensed S6 from assumed 40 C to saturated-liquid feed condition at 85 C | F8: Duty only; excluded from TAC
A9: Pre-column condenser (S2+S4 -> S6) | B9: 0 | C9: =C4+C5 -> 805.86306 | D9: =B9+C9 -> 805.86306 | E9: Full condensation of Flash 1 and Flash 2 vapor streams | F9: Duty only; excluded from TAC
A10: Vacuum pump | B10: 0 | C10: 0 | D10: 20 | E10: Liquid-ring vacuum pump screening power | F10: Electricity included in TAC
A11: Liquid feed pump | B11: 0 | C11: 0 | D11: =Column!B22*SUMPRODUCT(Column!C4:C6,Inputs!C13:C15)/3600/Inputs!E25*(Inputs!B29-Inputs!B27)*100000/Inputs!E32/1000 -> 0.058290822 | E11: Pump S6 from 0.08 bar to 1.013 bar; hydraulic power/efficiency | F11: Electricity included in TAC
A12: Total heating duty | D12: =D4+D5+D6+D8 -> 1576.5049 | E12: Flash 1 + Flash 2 + feed heater + column reboiler | F12: Energy-balance total
A13: Total cooling duty | D13: =D7+D9 -> 1166.0487 | E13: Pre-column condenser + column condenser | F13: Energy-balance total
A15: Cost parameter | B15: Value | C15: Unit | D15: Formula/assumption
A16: Operating hours | B16: 8000 | C16: h/year | D16: Input
A17: Steam cost | B17: 18 | C17: $/GJ | D17: Input
A18: Cooling cost | B18: 0.4 | C18: $/GJ | D18: Input
A19: Electricity cost | B19: 0.12 | C19: $/kWh | D19: Input
A20: Installed factor | B20: 2.7 | C20: - | D20: Installed = bare x factor
A21: Capital recovery factor | B21: 0.2 | C21: 1/year | D21: Annualized capital = CRF x installed
A23: Cost item | B23: Bare cost ($) | C23: Equation | D23: Annualized / operating ($/year) | E23: Category
A24: Column shell | B24: =60000*(Column!B31/0.5)^1.1*(Column!B33/10)^0.8 -> 97151.69 | C24: 60000*(D/0.5)^1.1*(H/10)^0.8 | E24: Capital
A25: Sieve trays | B25: =1200*Column!B29*(Column!B31/0.5)^1.2 -> 35938.909 | C25: 1200*Ntrays*(D/0.5)^1.2 | E25: Capital
A26: Flash drum 1 | B26: 18000 | C26: 18000*(Vessel volume/1 m3)^0.6 | E26: Capital
A27: Flash drum 2 | B27: 13248.395 | C27: 18000*(Vessel volume/1 m3)^0.6 | E27: Capital
A28: Vacuum + liquid feed pumps | B28: 40000 | C28: $35,000 vacuum pump + $5,000 small liquid pump allowance | E28: Capital
A29: Column reboiler + total condenser | B29: =15000*(D6/100)^0.65+15000*(D7/100)^0.65 -> 72143.567 | C29: SUM[15000*(Q/100)^0.65] for column thermal equipment only | E29: Capital
A30: Bare module subtotal | B30: =SUM(B24:B29) -> 276482.56 | C30: Sum of included bare equipment only | E30: Capital
A31: Installed capital | B31: =B30*$B$20 -> 746502.91 | C31: Bare subtotal*installed factor | E31: Capital
A32: Annualized capital | C32: Installed capital*capital recovery factor | D32: =B31*$B$21 -> 149300.58 | E32: Annual
A33: Steam utility | C33: Column reboiler duty only | D33: =D6*$B$16*0.0036*$B$17 -> 213507.59 | E33: Operating
A34: Cooling utility | C34: Column total condenser duty only | D34: =D7*$B$16*0.0036*$B$18 -> 4149.3381 | E34: Operating
A35: Pump electricity | C35: (Vacuum + liquid pump power)*hours*electricity price | D35: =(D10+D11)*$B$16*$B$19 -> 19255.959 | E35: Operating
A36: Total annualized cost | C36: Annualized capital + included utilities | D36: =SUM(D32:D35) -> 386213.47 | E36: TAC
A38: Reuse justification
A39: Methanol product | B39: Recycle to biodiesel transesterification reactor after quality check
A40: Water product | B40: Reuse as process wash/utility water if residual methanol specification is met
A41: Glycerol product | B41: Sell/use as crude glycerol feedstock; further polishing may be needed for pharma-grade glycerol
A42: Safety note | B42: Methanol service requires closed equipment, grounding, ventilation, relief devices, and LEL/toxic exposure controls.
A44: V4 cost-treatment summary
A45: Energy-balance heating duty | B45: Flash 1 + Flash 2 + feed heater + column reboiler | C45: =D12 -> 1576.5049 | D45: kW
...

Sheet Sensitivity
A1: Reflux Ratio Sensitivity
A3: R/Rmin | B3: R | C3: Theoretical stages | D3: Actual trays | E3: Reboiler duty (kW) | F3: Estimated TAC ($/year)
A4: 1.2 | B4: =A4*Column!$B$18 -> 1.7512026 | C4: 13.31459 | D4: 20 | E4: =(B4+1)*Column!$B$15*(Column!$G$5*Inputs!$E$14+Column!$G$4*Inputs!$E$13)/3.6 -> 411.85878 | F4: =(((60000*(Column!$B$31/0.5)^1.1*((2.5+D4*Column!$B$32)/10)^0.8)+(1200*D4*(Column!$B$31/0.5)^1.2)+(Energy_Cost!$B$26+Energy_Cost!$B$27+Energy_Cost!$B$28)+(15000*(E4/100)^0.65+15000*(((E4*Energy_Cost!$D$7/Energy_Cost!$D$6))/100)^0.65))*Energy_Cost!$B$20*Energy_Cost!$B$21)+(E4*Energy_Cost!$B$16*0.0036*Energy_Cost!$B$17)+(((E4*Energy_Cost!$D$7/Energy_Cost!$D$6))*Energy_Cost!$B$16*0.0036*Energy_Cost!$B$18)+(Energy_Cost!$D$35) -> 386213.47
A5: 1.3 | B5: =A5*Column!$B$18 -> 1.8971361 | C5: 12.060127 | D5: 19 | E5: =(B5+1)*Column!$B$15*(Column!$G$5*Inputs!$E$14+Column!$G$4*Inputs!$E$13)/3.6 -> 433.70523 | F5: =(((60000*(Column!$B$31/0.5)^1.1*((2.5+D5*Column!$B$32)/10)^0.8)+(1200*D5*(Column!$B$31/0.5)^1.2)+(Energy_Cost!$B$26+Energy_Cost!$B$27+Energy_Cost!$B$28)+(15000*(E5/100)^0.65+15000*(((E5*Energy_Cost!$D$7/Energy_Cost!$D$6))/100)^0.65))*Energy_Cost!$B$20*Energy_Cost!$B$21)+(E5*Energy_Cost!$B$16*0.0036*Energy_Cost!$B$17)+(((E5*Energy_Cost!$D$7/Energy_Cost!$D$6))*Energy_Cost!$B$16*0.0036*Energy_Cost!$B$18)+(Energy_Cost!$D$35) -> 396470.61
A6: 1.5 | B6: =A6*Column!$B$18 -> 2.1890032 | C6: 10.490772 | D6: 16 | E6: =(B6+1)*Column!$B$15*(Column!$G$5*Inputs!$E$14+Column!$G$4*Inputs!$E$13)/3.6 -> 477.39813 | F6: =(((60000*(Column!$B$31/0.5)^1.1*((2.5+D6*Column!$B$32)/10)^0.8)+(1200*D6*(Column!$B$31/0.5)^1.2)+(Energy_Cost!$B$26+Energy_Cost!$B$27+Energy_Cost!$B$28)+(15000*(E6/100)^0.65+15000*(((E6*Energy_Cost!$D$7/Energy_Cost!$D$6))/100)^0.65))*Energy_Cost!$B$20*Energy_Cost!$B$21)+(E6*Energy_Cost!$B$16*0.0036*Energy_Cost!$B$17)+(((E6*Energy_Cost!$D$7/Energy_Cost!$D$6))*Energy_Cost!$B$16*0.0036*Energy_Cost!$B$18)+(Energy_Cost!$D$35) -> 414213.65
A7: 1.8 | B7: =A7*Column!$B$18 -> 2.6268039 | C7: 9.1990989 | D7: 15 | E7: =(B7+1)*Column!$B$15*(Column!$G$5*Inputs!$E$14+Column!$G$4*Inputs!$E$13)/3.6 -> 542.93749 | F7: =(((60000*(Column!$B$31/0.5)^1.1*((2.5+D7*Column!$B$32)/10)^0.8)+(1200*D7*(Column!$B$31/0.5)^1.2)+(Energy_Cost!$B$26+Energy_Cost!$B$27+Energy_Cost!$B$28)+(15000*(E7/100)^0.65+15000*(((E7*Energy_Cost!$D$7/Energy_Cost!$D$6))/100)^0.65))*Energy_Cost!$B$20*Energy_Cost!$B$21)+(E7*Energy_Cost!$B$16*0.0036*Energy_Cost!$B$17)+(((E7*Energy_Cost!$D$7/Energy_Cost!$D$6))*Energy_Cost!$B$16*0.0036*Energy_Cost!$B$18)+(Energy_Cost!$D$35) -> 449911.91
A8: 2 | B8: =A8*Column!$B$18 -> 2.9186709 | C8: 8.6632884 | D8: 13 | E8: =(B8+1)*Column!$B$15*(Column!$G$5*Inputs!$E$14+Column!$G$4*Inputs!$E$13)/3.6 -> 586.63039 | F8: =(((60000*(Column!$B$31/0.5)^1.1*((2.5+D8*Column!$B$32)/10)^0.8)+(1200*D8*(Column!$B$31/0.5)^1.2)+(Energy_Cost!$B$26+Energy_Cost!$B$27+Energy_Cost!$B$28)+(15000*(E8/100)^0.65+15000*(((E8*Energy_Cost!$D$7/Energy_Cost!$D$6))/100)^0.65))*Energy_Cost!$B$20*Energy_Cost!$B$21)+(E8*Energy_Cost!$B$16*0.0036*Energy_Cost!$B$17)+(((E8*Energy_Cost!$D$7/Energy_Cost!$D$6))*Energy_Cost!$B$16*0.0036*Energy_Cost!$B$18)+(Energy_Cost!$D$35) -> 470001.88
A10: Selected case | B10: 1.2 | C10: The 1.20 R/Rmin case gives the lowest screening TAC under the revised rule: pre-column heaters/HEX duties are calculated but excluded from TAC.
A11: Interpretation | B11: Higher reflux reduces stages but increases the costed column reboiler/condenser duties. Pre-column duties remain outside TAC.
A12: Caution | B12: Cost functions are order-of-magnitude screening estimates. Electricity price and pump costs are assumptions.
A13: Final selected R | B13: =Column!B19 -> 1.7512026 | C13: Used in Column and Hydraulics sheets.

Sheet References
A1: References and Source Notes
A3: No. | B3: Source | C3: Used for
A4: 1 | B4: CHE 312 Course Staff, CHE 312 Term Project Description - Spring 2026 | C4: Project statement: 100 kmol/h feed, allowed units, purity targets, report requirements
A5: 2 | B5: CHE 312 Course Staff, CHE 312 Project Groups - Spring 2026 | C5: Group 20 feed composition and group assignment
A6: 3 | B6: CHE 312 Course Staff, Chapter 6: Internal Design of a Sieve-Plate Column | C6: Sieve-tray diameter, flooding, weeping, pressure drop, downcomer backup and residence time
A7: 4 | B7: CHE 312 Course Staff, Handout 1: Multicomponent Mixtures and Shortcut Distillation Methods | C7: Shortcut column calculations, Fenske/Underwood/Gilliland basis and feed-stage logic
A8: 5 | B8: CHE 312 Course Staff, Handout 2: Internal Design of Plate Columns | C8: Capacity factor, entrainment, orifice, aeration and K2 charts
A9: 6 | B9: NIST Chemistry WebBook: Methyl Alcohol (Methanol), CAS No. 67-56-1 | C9: Antoine equation and molecular-weight/property basis for methanol
A10: 7 | B10: NIST Chemistry WebBook: Water, CAS No. 7732-18-5 | C10: Antoine equation and molecular-weight/property basis for water
A11: 8 | B11: NIST Chemistry WebBook: Glycerol (Glycerin), CAS No. 56-81-5 | C11: Glycerol molecular weight and property identity
A12: 9 | B12: OSHA Chemical Data: Methyl Alcohol (Methanol), CAS No. 67-56-1 | C12: Methanol flammability limits, flash point and safety properties
A13: 10 | B13: NIOSH Pocket Guide to Chemical Hazards: Methyl Alcohol | C13: Methanol emergency exposure and handling basis
A14: 11 | B14: G. Towler and R. K. Sinnott, Chemical Engineering Design, 2nd ed. | C14: Preliminary cost functions and design economics context
A15: 12 | B15: R. K. Sinnott, Coulson & Richardson's Chemical Engineering, Vol. 6, 4th ed. | C15: Column design and cost-estimation background
... A18: 15 | B18: D. W. Green and M. Z. Southard, Perry's Chemical Engineers' Handbook, 9th ed. | C18: Physical-property and general process-design reference

Sheet McCabe_Thiele
A1: McCabe–Thiele Check for Methanol–Water Column
A5: Input / parameter | B5: Symbol | C5: Value / Formula | D5: Unit | E5: Short note
A6: Distillate methanol mole fraction | B6: xD | C6: =Column!B9 -> 0.95 | D6: - | E6: Top product specification | G6: x | H6: Equilibrium y | I6: Diagonal y=x | J6: Rectifying y | K6: Stripping y | L6: q-line x=xF
A7: Bottoms methanol mole fraction | B7: xB | C7: =Column!B10 -> 0.005 | D7: - | E7: Chosen to make water product about 99.5 mol% | G7: 0 | H7: =$C$9*G7/(1+($C$9-1)*G7) -> 0 | I7: =G7 -> 0 | J7: =$C$16*G7+$C$17 -> 0.34530355 | K7: =$C$19*G7+$C$20 -> -0.0081938733 | L7: =$C$8 -> 0.17654991
A8: Column feed methanol mole fraction | B8: xF | C8: =Column!C4 -> 0.17654991 | D8: - | E8: Combined Flash 1 vapor + Flash 2 vapor | G8: 0.05 | H8: =$C$9*G8/(1+($C$9-1)*G8) -> 0.19148936 | I8: =G8 -> 0.05 | J8: =$C$16*G8+$C$17 -> 0.37712967 | K8: =$C$19*G8+$C$20 -> 0.12374486 | L8: =$C$8 -> 0.17654991
A9: Relative volatility | B9: alpha | C9: =Column!B11 -> 4.5 | D9: - | E9: Assumed constant average MeOH/H2O relative volatility | G9: 0.1 | H9: =$C$9*G9/(1+($C$9-1)*G9) -> 0.33333333 | I9: =G9 -> 0.1 | J9: =$C$16*G9+$C$17 -> 0.4089558 | K9: =$C$19*G9+$C$20 -> 0.25568359 | L9: =$C$8 -> 0.17654991
A10: Feed thermal condition | B10: q | C10: =Column!B12 -> 1 | D10: - | E10: q = 1 means saturated liquid feed | G10: 0.15 | H10: =$C$9*G10/(1+($C$9-1)*G10) -> 0.44262295 | I10: =G10 -> 0.15 | J10: =$C$16*G10+$C$17 -> 0.44078193 | K10: =$C$19*G10+$C$20 -> 0.38762233 | L10: =$C$8 -> 0.17654991
A11: Equilibrium vapor at xF | B11: yF* | C11: =C9*C8/(1+(C9-1)*C8) -> 0.49104547 | D11: - | E11: Point on equilibrium curve at x = xF, not actual feed vapor composition | G11: 0.2 | H11: =$C$9*G11/(1+($C$9-1)*G11) -> 0.52941176 | I11: =G11 -> 0.2 | J11: =$C$16*G11+$C$17 -> 0.47260806 | K11: =$C$19*G11+$C$20 -> 0.51956106 | L11: =$C$8 -> 0.17654991
A12: Minimum line slope | B12: mmin | C12: =(C6-C11)/(C6-C8) -> 0.5933861 | D12: - | E12: Slope of line through (xD,xD) and (xF,yF*) | G12: 0.25 | H12: =$C$9*G12/(1+($C$9-1)*G12) -> 0.6 | I12: =G12 -> 0.25 | J12: =$C$16*G12+$C$17 -> 0.50443419 | K12: =$C$19*G12+$C$20 -> 0.65149979 | L12: =$C$8 -> 0.17654991
A13: Minimum reflux ratio | B13: Rmin | C13: =C12/(1-C12) -> 1.4593355 | D13: - | E13: Since rectifying slope m = R/(R+1) | G13: 0.3 | H13: =$C$9*G13/(1+($C$9-1)*G13) -> 0.65853659 | I13: =G13 -> 0.3 | J13: =$C$16*G13+$C$17 -> 0.53626032 | K13: =$C$19*G13+$C$20 -> 0.78343853 | L13: =$C$8 -> 0.17654991
A14: Selected R/Rmin | B14: R/Rmin | C14: =Column!B13 -> 1.2 | D14: - | E14: Design choice from sensitivity table | G14: 0.35 | H14: =$C$9*G14/(1+($C$9-1)*G14) -> 0.70786517 | I14: =G14 -> 0.35 | J14: =$C$16*G14+$C$17 -> 0.56808645 | K14: =$C$19*G14+$C$20 -> 0.91537726 | L14: =$C$8 -> 0.17654991
A15: Selected reflux ratio | B15: R | C15: =C14*C13 -> 1.7512026 | D15: - | E15: Actual reflux ratio used in McCabe stepping | G15: 0.4 | H15: =$C$9*G15/(1+($C$9-1)*G15) -> 0.75 | I15: =G15 -> 0.4 | J15: =$C$16*G15+$C$17 -> 0.59991258 | K15: =$C$19*G15+$C$20 -> 1.047316 | L15: =$C$8 -> 0.17654991
A16: Rectifying slope | B16: mR | C16: =C15/(C15+1) -> 0.63652258 | D16: - | E16: Slope of rectifying operating line | G16: 0.45 | H16: =$C$9*G16/(1+($C$9-1)*G16) -> 0.78640777 | I16: =G16 -> 0.45 | J16: =$C$16*G16+$C$17 -> 0.63173871 | K16: =$C$19*G16+$C$20 -> 1.1792547 | L16: =$C$8 -> 0.17654991
A17: Rectifying intercept | B17: bR | C17: =C6/(C15+1) -> 0.34530355 | D17: - | E17: Intercept of rectifying operating line | G17: 0.5 | H17: =$C$9*G17/(1+($C$9-1)*G17) -> 0.81818182 | I17: =G17 -> 0.5 | J17: =$C$16*G17+$C$17 -> 0.66356484 | K17: =$C$19*G17+$C$20 -> 1.3111935 | L17: =$C$8 -> 0.17654991
A18: Intersection at feed | B18: yint | C18: =C16*C8+C17 -> 0.45768155 | D18: - | E18: Where q-line x=xF meets rectifying line | G18: 0.55 | H18: =$C$9*G18/(1+($C$9-1)*G18) -> 0.84615385 | I18: =G18 -> 0.55 | J18: =$C$16*G18+$C$17 -> 0.69539097 | K18: =$C$19*G18+$C$20 -> 1.4431322 | L18: =$C$8 -> 0.17654991
A19: Stripping slope | B19: mS | C19: =(C18-C7)/(C8-C7) -> 2.6387747 | D19: - | E19: Line through (xF,yint) and (xB,xB) | G19: 0.6 | H19: =$C$9*G19/(1+($C$9-1)*G19) -> 0.87096774 | I19: =G19 -> 0.6 | J19: =$C$16*G19+$C$17 -> 0.7272171 | K19: =$C$19*G19+$C$20 -> 1.5750709 | L19: =$C$8 -> 0.17654991
A20: Stripping intercept | B20: bS | C20: =C7-C19*C7 -> -0.0081938733 | D20: - | E20: Intercept of stripping line | G20: 0.65 | H20: =$C$9*G20/(1+($C$9-1)*G20) -> 0.89312977 | I20: =G20 -> 0.65 | J20: =$C$16*G20+$C$17 -> 0.75904322 | K20: =$C$19*G20+$C$20 -> 1.7070097 | L20: =$C$8 -> 0.17654991
A21: McCabe theoretical stages | B21: N_th | C21: =MATCH("Reached xB",F32:F59,0) -> 14 | D21: - | E21: Full horizontal-equilibrium steps listed below | G21: 0.7 | H21: =$C$9*G21/(1+($C$9-1)*G21) -> 0.91304348 | I21: =G21 -> 0.7 | J21: =$C$16*G21+$C$17 -> 0.79086935 | K21: =$C$19*G21+$C$20 -> 1.8389484 | L21: =$C$8 -> 0.17654991
A22: Rounded theoretical stages | B22: N_round | C22: =ROUNDUP(C21,0) -> 14 | D22: - | E22: Used to compare with shortcut result | G22: 0.75 | H22: =$C$9*G22/(1+($C$9-1)*G22) -> 0.93103448 | I22: =G22 -> 0.75 | J22: =$C$16*G22+$C$17 -> 0.82269548 | K22: =$C$19*G22+$C$20 -> 1.9708871 | L22: =$C$8 -> 0.17654991
A23: Overall tray efficiency | B23: E | C23: =Column!B14 -> 0.7 | D23: - | E23: Assumed efficiency for preliminary design | G23: 0.8 | H23: =$C$9*G23/(1+($C$9-1)*G23) -> 0.94736842 | I23: =G23 -> 0.8 | J23: =$C$16*G23+$C$17 -> 0.85452161 | K23: =$C$19*G23+$C$20 -> 2.1028259 | L23: =$C$8 -> 0.17654991
A24: Actual trays | B24: N_actual | C24: =ROUNDUP(C22/C23,0) -> 20 | D24: trays | E24: Actual trays = theoretical stages / efficiency | G24: 0.85 | H24: =$C$9*G24/(1+($C$9-1)*G24) -> 0.96226415 | I24: =G24 -> 0.85 | J24: =$C$16*G24+$C$17 -> 0.88634774 | K24: =$C$19*G24+$C$20 -> 2.2347646 | L24: =$C$8 -> 0.17654991
G25: 0.9 | H25: =$C$9*G25/(1+($C$9-1)*G25) -> 0.97590361 | I25: =G25 -> 0.9 | J25: =$C$16*G25+$C$17 -> 0.91817387 | K25: =$C$19*G25+$C$20 -> 2.3667033 | L25: =$C$8 -> 0.17654991
G26: 0.95 | H26: =$C$9*G26/(1+($C$9-1)*G26) -> 0.98843931 | I26: =G26 -> 0.95 | J26: =$C$16*G26+$C$17 -> 0.95 | K26: =$C$19*G26+$C$20 -> 2.4986421 | L26: =$C$8 -> 0.17654991
G27: 1 | H27: =$C$9*G27/(1+($C$9-1)*G27) -> 1 | I27: =G27 -> 1 | J27: =$C$16*G27+$C$17 -> 0.98182613 | K27: =$C$19*G27+$C$20 -> 2.6305808 | L27: =$C$8 -> 0.17654991
A30: McCabe stepping table | J30: Course-note logic used | K30: Explanation
A31: Stage | B31: y start | C31: x from equilibrium | D31: Section used | E31: y next from operating line | F31: Stop check | G31: Short meaning | H31: Count | J31: CMO / Lewis method | K31: As in the Chapter 4 notes, constant molal overflow allows use of operating lines instead of full energy balances.
A32: 1 | B32: =$C$6 -> 0.95 | C32: =B32/($C$9-($C$9-1)*B32) -> 0.80851064 | D32: =IF(C32>$C$8,"Rectifying","Stripping") -> Rectifying | E32: =IF(C32>$C$8,$C$16*C32+$C$17,$C$19*C32+$C$20) -> 0.85993883 | F32: =IF(C32<=$C$7,"Reached xB","Continue") -> Continue | G32: =IF(C32>$C$8,"Above feed tray","Below feed tray") -> Above feed tray | H32: =IF(AND(A32>=1,C32>0),1,0) -> 1 | J32: Total condenser | K32: For a total condenser, y1 = xD. The first horizontal step starts at y = xD.
A33: 2 | B33: =E32 -> 0.85993883 | C33: =B33/($C$9-($C$9-1)*B33) -> 0.57705723 | D33: =IF(C33>$C$8,"Rectifying","Stripping") -> Rectifying | E33: =IF(C33>$C$8,$C$16*C33+$C$17,$C$19*C33+$C$20) -> 0.7126135 | F33: =IF(C33<=$C$7,"Reached xB","Continue") -> Continue | G33: =IF(C33>$C$8,"Above feed tray","Below feed tray") -> Above feed tray | H33: =IF(AND(A33>=1,C33>0),1,0) -> 1 | J33: Rectifying operating line | K33: y = [R/(R+1)] x + [xD/(R+1)]. This matches the course notes for the enriching section.
A34: 3 | B34: =E33 -> 0.7126135 | C34: =B34/($C$9-($C$9-1)*B34) -> 0.35526711 | D34: =IF(C34>$C$8,"Rectifying","Stripping") -> Rectifying | E34: =IF(C34>$C$8,$C$16*C34+$C$17,$C$19*C34+$C$20) -> 0.57143908 | F34: =IF(C34<=$C$7,"Reached xB","Continue") -> Continue | G34: =IF(C34>$C$8,"Above feed tray","Below feed tray") -> Above feed tray | H34: =IF(AND(A34>=1,C34>0),1,0) -> 1 | J34: q-line | K34: q = 1 is saturated liquid, so the q-line is vertical at x = xF. This is valid only if the combined flash vapor feed is condensed before entering the column.
A35: 4 | B35: =E34 -> 0.57143908 | C35: =B35/($C$9-($C$9-1)*B35) -> 0.228579 | D35: =IF(C35>$C$8,"Rectifying","Stripping") -> Rectifying | E35: =IF(C35>$C$8,$C$16*C35+$C$17,$C$19*C35+$C$20) -> 0.49079924 | F35: =IF(C35<=$C$7,"Reached xB","Continue") -> Continue | G35: =IF(C35>$C$8,"Above feed tray","Below feed tray") -> Above feed tray | H35: =IF(AND(A35>=1,C35>0),1,0) -> 1 | J35: yF* | K35: yF* is the equilibrium vapor composition at xF. It is read/calculated from the equilibrium curve and used to estimate Rmin.
A36: 5 | B36: =E35 -> 0.49079924 | C36: =B36/($C$9-($C$9-1)*B36) -> 0.17640672 | D36: =IF(C36>$C$8,"Rectifying","Stripping") -> Stripping | E36: =IF(C36>$C$8,$C$16*C36+$C$17,$C$19*C36+$C$20) -> 0.4573037 | F36: =IF(C36<=$C$7,"Reached xB","Continue") -> Continue | G36: =IF(C36>$C$8,"Above feed tray","Below feed tray") -> Below feed tray | H36: =IF(AND(A36>=1,C36>0),1,0) -> 1 | J36: Stripping operating line | K36: For q = 1, the stripping line is drawn through the feed intersection point and (xB, xB).
A37: 6 | B37: =E36 -> 0.4573037 | C37: =B37/($C$9-($C$9-1)*B37) -> 0.15772155 | D37: =IF(C37>$C$8,"Rectifying","Stripping") -> Stripping | E37: =IF(C37>$C$8,$C$16*C37+$C$17,$C$19*C37+$C$20) -> 0.40799776 | F37: =IF(C37<=$C$7,"Reached xB","Continue") -> Continue | G37: =IF(C37>$C$8,"Above feed tray","Below feed tray") -> Below feed tray | H37: =IF(AND(A37>=1,C37>0),1,0) -> 1 | J37: Stage count | K37: Stepping between the equilibrium curve and operating lines gives approximately 14 theoretical stages, consistent with the shortcut result.
A38: 7 | B38: =E37 -> 0.40799776 | C38: =B38/($C$9-($C$9-1)*B38) -> 0.13281143 | D38: =IF(C38>$C$8,"Rectifying","Stripping") -> Stripping | E38: =IF(C38>$C$8,$C$16*C38+$C$17,$C$19*C38+$C$20) -> 0.34226556 | F38: =IF(C38<=$C$7,"Reached xB","Continue") -> Continue | G38: =IF(C38>$C$8,"Above feed tray","Below feed tray") -> Below feed tray | H38: =IF(AND(A38>=1,C38>0),1,0) -> 1 | J38: Tray efficiency | K38: E = 0.70 is an assumed overall tray efficiency. Actual trays = theoretical stages / E.
A39: 8 | B39: =E38 -> 0.34226556 | C39: =B39/($C$9-($C$9-1)*B39) -> 0.1036518 | D39: =IF(C39>$C$8,"Rectifying","Stripping") -> Stripping | E39: =IF(C39>$C$8,$C$16*C39+$C$17,$C$19*C39+$C$20) -> 0.26531988 | F39: =IF(C39<=$C$7,"Reached xB","Continue") -> Continue | G39: =IF(C39>$C$8,"Above feed tray","Below feed tray") -> Below feed tray | H39: =IF(AND(A39>=1,C39>0),1,0) -> 1
A40: 9 | B40: =E39 -> 0.26531988 | C40: =B40/($C$9-($C$9-1)*B40) -> 0.074290568 | D40: =IF(C40>$C$8,"Rectifying","Stripping") -> Stripping | E40: =IF(C40>$C$8,$C$16*C40+$C$17,$C$19*C40+$C$20) -> 0.18784219 | F40: =IF(C40<=$C$7,"Reached xB","Continue") -> Continue | G40: =IF(C40>$C$8,"Above feed tray","Below feed tray") -> Below feed tray | H40: =IF(AND(A40>=1,C40>0),1,0) -> 1
A41: 10 | B41: =E40 -> 0.18784219 | C41: =B41/($C$9-($C$9-1)*B41) -> 0.048884746 | D41: =IF(C41>$C$8,"Rectifying","Stripping") -> Stripping | E41: =IF(C41>$C$8,$C$16*C41+$C$17,$C$19*C41+$C$20) -> 0.12080196 | F41: =IF(C41<=$C$7,"Reached xB","Continue") -> Continue | G41: =IF(C41>$C$8,"Above feed tray","Below feed tray") -> Below feed tray | H41: =IF(AND(A41>=1,C41>0),1,0) -> 1
A42: 11 | B42: =E41 -> 0.12080196 | C42: =B42/($C$9-($C$9-1)*B42) -> 0.029628706 | D42: =IF(C42>$C$8,"Rectifying","Stripping") -> Stripping | E42: =IF(C42>$C$8,$C$16*C42+$C$17,$C$19*C42+$C$20) -> 0.069989605 | F42: =IF(C42<=$C$7,"Reached xB","Continue") -> Continue | G42: =IF(C42>$C$8,"Above feed tray","Below feed tray") -> Below feed tray | H42: =IF(AND(A42>=1,C42>0),1,0) -> 1
A43: 12 | B43: =E42 -> 0.069989605 | C43: =B43/($C$9-($C$9-1)*B43) -> 0.01644865 | D43: =IF(C43>$C$8,"Rectifying","Stripping") -> Stripping | E43: =IF(C43>$C$8,$C$16*C43+$C$17,$C$19*C43+$C$20) -> 0.035210408 | F43: =IF(C43<=$C$7,"Reached xB","Continue") -> Continue | G43: =IF(C43>$C$8,"Above feed tray","Below feed tray") -> Below feed tray | H43: =IF(AND(A43>=1,C43>0),1,0) -> 1
A44: 13 | B44: =E43 -> 0.035210408 | C44: =B44/($C$9-($C$9-1)*B44) -> 0.0080448503 | D44: =IF(C44>$C$8,"Rectifying","Stripping") -> Stripping | E44: =IF(C44>$C$8,$C$16*C44+$C$17,$C$19*C44+$C$20) -> 0.013034674 | F44: =IF(C44<=$C$7,"Reached xB","Continue") -> Continue | G44: =IF(C44>$C$8,"Above feed tray","Below feed tray") -> Below feed tray | H44: =IF(AND(A44>=1,C44>0),1,0) -> 1
A45: 14 | B45: =E44 -> 0.013034674 | C45: =B45/($C$9-($C$9-1)*B45) -> 0.0029262609 | D45: =IF(C45>$C$8,"Rectifying","Stripping") -> Stripping | E45: =IF(C45>$C$8,$C$16*C45+$C$17,$C$19*C45+$C$20) -> -0.00047213027 | F45: =IF(C45<=$C$7,"Reached xB","Continue") -> Reached xB | G45: =IF(C45>$C$8,"Above feed tray","Below feed tray") -> Below feed tray | H45: =IF(AND(A45>=1,C45>0),1,0) -> 1

Sheet Stream_Summary_Final
A1: Final Stream Summary for Report Synchronization
A4: Stream | B4: Description | C4: Total kmol/h | D4: MeOH kmol/h | E4: Water kmol/h | F4: Glycerol kmol/h | G4: MeOH mol% | H4: Water mol% | I4: Glycerol mol% | J4: Phase before/after conditioning
A5: S1 | B5: Fresh feed | C5: =Feed!C8 -> 100 | D5: =Feed!C4 -> 12.92 | E5: =Feed!C5 -> 61.18 | F5: =Feed!C6 -> 25.9 | G5: =D5/C5 -> 0.1292 | H5: =E5/C5 -> 0.6118 | I5: =F5/C5 -> 0.259 | J5: Liquid feed
A6: S2 | B6: Flash 1 vapor | C6: =Flash!F14 -> 37.611681 | D6: =Flash!F10 -> 9.5867592 | E6: =Flash!F11 -> 28.024907 | F6: =Flash!F12 -> 1.5614172e-05 | G6: =D6/C6 -> 0.25488781 | H6: =E6/C6 -> 0.74511177 | I6: =F6/C6 -> 4.1514157e-07 | J6: Vapor
A7: S3 | B7: Flash 1 liquid | C7: =Flash!G14 -> 62.388319 | D7: =Flash!G10 -> 3.3332408 | E7: =Flash!G11 -> 33.155093 | F7: =Flash!G12 -> 25.899984 | G7: =D7/C7 -> 0.053427323 | H7: =E7/C7 -> 0.53143111 | I7: =F7/C7 -> 0.41514157 | J7: Liquid
A8: S4 | B8: Flash 2 vapor | C8: =Flash!F29 -> 35.378381 | D8: =Flash!F25 -> 3.2996296 | E8: =Flash!F26 -> 32.078718 | F8: =Flash!F27 -> 3.3924489e-05 | G8: =D8/C8 -> 0.093266834 | H8: =E8/C8 -> 0.90673221 | I8: =F8/C8 -> 9.5890449e-07 | J8: Vapor
A9: S5 | B9: Glycerol product | C9: =Flash!G29 -> 27.009938 | D9: =Flash!G25 -> 0.033611257 | E9: =Flash!G26 -> 1.0763758 | F9: =Flash!G27 -> 25.89995 | G9: =D9/C9 -> 0.0012444034 | H9: =E9/C9 -> 0.039851103 | I9: =F9/C9 -> 0.95890449 | J9: Liquid product
A10: S6 | B10: Column feed after condenser/pump/feed heater | C10: =Column!B22 -> 72.990062 | D10: =Column!B4 -> 12.886389 | E10: =Column!B5 -> 60.103624 | F10: =Column!B6 -> 4.9538661e-05 | G10: =D10/C10 -> 0.17654991 | H10: =E10/C10 -> 0.82344941 | I10: =F10/C10 -> 6.7870419e-07 | J10: Saturated liquid
A11: S7 | B11: Methanol product / distillate | C11: =Column!D4+Column!D5+Column!D6 -> 13.250199 | D11: =Column!D4 -> 12.587689 | E11: =Column!D5 -> 0.66250997 | F11: =Column!D6 -> 0 | G11: =D11/C11 -> 0.95 | H11: =E11/C11 -> 0.05 | I11: =F11/C11 -> 0 | J11: Liquid product
A12: S8 | B12: Water product / bottoms | C12: =Column!F4+Column!F5+Column!F6 -> 59.739863 | D12: =Column!F4 -> 0.29869932 | E12: =Column!F5 -> 59.441114 | F12: =Column!F6 -> 4.9538661e-05 | G12: =D12/C12 -> 0.005 | H12: =E12/C12 -> 0.99499917 | I12: =F12/C12 -> 8.2923961e-07 | J12: Liquid product
A16: Check | B16: Formula / basis | C16: Value
A17: Overall total balance | B17: S1 - S5 - S7 - S8 | C17: =C5-C9-C11-C12 -> 0
A18: Column total balance | B18: S6 - S7 - S8 | C18: =C10-C11-C12 -> 0
A19: Methanol purity | B19: S7 MeOH mol% | C19: =G11 -> 0.95
A20: Water purity | B20: S8 Water mol% | C20: =H12 -> 0.99499917
A21: Glycerol purity | B21: S5 Gly mol% | C21: =I9 -> 0.95890449
A22: Methanol recovery | B22: S7 MeOH / S1 MeOH | C22: =D11/D5 -> 0.97427937
A23: Water recovery | B23: S8 Water / S1 Water | C23: =E12/E5 -> 0.97157755

Sheet Hydraulics_TopBottom
A1: Top/Bottom Section Hydraulic Screening
A4: Parameter | B4: Rectifying section | C4: Unit | D4: Basis / formula | E4: Status | F4: Stripping section | G4: Unit | H4: Basis / formula | I4: Status
A5: Main liquid flow L | B5: =Column!B19*Column!B15 -> 23.203783 | C5: kmol/h | D5: R*D | E5: Info | F5: =Column!B19*Column!B15+Column!B22 -> 96.193846 | G5: kmol/h | H5: Approx. Lbar = L + F for q=1 | I5: Info
A6: Main vapor flow V | B6: =Column!B20 -> 36.453983 | C6: kmol/h | D6: (R+1)D | E6: Info | F6: =Column!B20 -> 36.453983 | G6: kmol/h | H6: CMO screening same vapor molar flow | I6: Info
A7: Average liquid/vapor MW | B7: =SUMPRODUCT(Column!E4:E6,Inputs!C13:C15) -> 31.34057 | C7: kg/kmol | D7: distillate composition | E7: Info | F7: =SUMPRODUCT(Column!G4:G6,Inputs!C13:C15) -> 18.085494 | G7: kg/kmol | H7: bottom composition | I7: Info
A8: Gdot | B8: =B6*B7/3600 -> 0.31735794 | C8: kg/s | D8: V*MW/3600 | E8: Info | F8: =F6*F7/3600 -> 0.18313564 | G8: kg/s | H8: V*MW/3600 | I8: Info
A9: Ldot | B9: =B5*B7/3600 -> 0.2020055 | C9: kg/s | D9: L*MW/3600 | E9: Info | F9: =F5*SUMPRODUCT(Column!C4:C6,Inputs!C13:C15)/3600 -> 0.54754994 | G9: kg/s | H9: Lbar*feed MW/3600 approx. | I9: Info
A10: Assumed vapor density rhoG | B10: =Inputs!B28*100000*(B7/1000)/(8.314*(68+273.15)) -> 0.62659391 | C10: kg/m3 | D10: ideal vapor at 68 C, 1.013 bar | E10: Info | F10: =Hydraulics!B6 -> 0.6 | G10: kg/m3 | H10: from existing Hydraulics sheet | I10: Info
A11: Assumed liquid density rhoL | B11: 790 | C11: kg/m3 | D11: methanol-rich liquid estimate | E11: Assumed | F11: =Hydraulics!B7 -> 950 | G11: kg/m3 | H11: from existing Hydraulics sheet | I11: Assumed
A12: Surface tension sigma | B12: 0.022 | C12: N/m | D12: methanol-rich estimate | E12: Assumed | F12: =Hydraulics!B8 -> 0.055 | G12: N/m | H12: from existing Hydraulics sheet | I12: Assumed
A13: K1 chart | B13: 0.06 | C13: m/s | D13: same chart basis | E13: Assumed | F13: =Hydraulics!B10 -> 0.06 | G13: m/s | H13: from existing Hydraulics sheet | I13: Assumed
A14: K1 corrected | B14: =B13*(B12/0.02)^0.2 -> 0.061154693 | C14: m/s | D14: surface tension correction | E14: Calc | F14: =F13*(F12/0.02)^0.2 -> 0.073454396 | G14: m/s | H14: surface tension correction | I14: Calc
A15: Flooding velocity uGF | B15: =B14*SQRT((B11-B10)/B10) -> 2.1705908 | C15: m/s | D15: K1c*sqrt((rhoL-rhoG)/rhoG) | E15: Calc | F15: =F14*SQRT((F11-F10)/F10) -> 2.9219096 | G15: m/s | H15: K1c*sqrt((rhoL-rhoG)/rhoG) | I15: Calc
A16: Design flooding fraction | B16: 0.7 | C16: - | D16: selected design fraction | E16: Assumed | F16: 0.7 | G16: - | H16: selected design fraction | I16: Assumed
A17: Downcomer area fraction a | B17: 0.0945 | C17: - | D17: same tray layout | E17: Assumed | F17: 0.0945 | G17: - | H17: same tray layout | I17: Assumed
A18: Required diameter | B18: =SQRT(4*B8/(PI()*B10*(B16*B15)*(1-B17))) -> 0.68462766 | C18: m | D18: from vapor continuity | F18: =SQRT(4*F8/(PI()*F10*(F16*F15)*(1-F17))) -> 0.45807779 | G18: m | H18: from vapor continuity
A19: Selected standard diameter | B19: =CEILING(MAX(B18,F18),0.05) -> 0.7 | C19: m | D19: max top/bottom, rounded up | F19: =B19 -> 0.7 | G19: m | H19: same column shell diameter
A20: Actual flooding fraction | B20: =B8/(B10*(PI()*B19^2/4)*(1-B17))/B15 -> 0.6695929 | C20: - | D20: actual vapor velocity / uGF | F20: =F8/(F10*(PI()*F19^2/4)*(1-F17))/F15 -> 0.29976465 | G20: - | H20: actual vapor velocity / uGF
A21: Flooding status | B21: =IF(B20<0.7,"OK","Check") -> OK | C21: - | D21: target below 70% | F21: =IF(F20<0.7,"OK","Check") -> OK | G21: - | H21: target below 70%
A22: Final selected diameter | B22: =B19 -> 0.7 | C22: m | D22: transferred to Column and Hydraulics | F22: =B19 -> 0.7 | G22: m | H22: same diameter used for both sections

Sheet Equipment_List
A1: Tagged Equipment List and Cost-Treatment Summary
A4: Tag | B4: Equipment | C4: Quantity | D4: Main function | E4: Duty / power | G4: Cost treatment
A5: E-01 | B5: Flash 1 Heater | C5: 1 | D5: Heat S1 to Flash 1 operating condition | E5: =Energy_Cost!D4 -> 625.14878
A6: FD-01 | B6: Flash Drum 1 | C6: 1 | D6: Initial methanol-water vapor recovery | E6: 90 C, 0.50 bar
A7: E-02 | B7: Flash 2 Heater | C7: 1 | D7: Heat S3 to Flash 2 operating condition | E7: =Energy_Cost!D5 -> 469.87715
A8: V-01 | B8: Pressure-Reducing Valve to FD-02 | C8: 1 | D8: Reduce S3 pressure before Flash 2 | E8: 0.50 -> 0.08 bar
A9: FD-02 | B9: Flash Drum 2 | C9: 1 | D9: Concentrate glycerol product | E9: 120 C, 0.08 bar
A10: V-02 | B10: S2 Pressure-Reducing Valve | C10: 1 | D10: Match S2 pressure to pre-column condenser | E10: 0.50 -> 0.08 bar
A11: E-03 | B11: Pre-column Condenser & Mixer | C11: 1 | D11: Fully condense S2+S4 before column | E11: =Energy_Cost!D9 -> 805.86306
A12: VP-01 | B12: Liquid-ring Vacuum Pump | C12: 1 | D12: Maintain vacuum on Flash 2/pre-column vapor system | E12: =Energy_Cost!D10 -> 20
A13: P-01 | B13: Column Feed Pump | C13: 1 | D13: Pump condensed S6 to column pressure | E13: =Energy_Cost!D11 -> 0.058290822
A14: E-04 | B14: Column Feed Heater | C14: 1 | D14: Bring S6 to saturated-liquid condition | E14: =Energy_Cost!D8 -> 69.620153
A15: COL-01 | B15: Sieve-Plate Distillation Column | C15: 1 | D15: Methanol-water separation | E15: 20 trays, D = 0.70 m
A16: E-05 | B16: Column Total Condenser | C16: 1 | D16: Condense column overhead vapor | E16: =Energy_Cost!D7 -> 360.1856
A17: RD-01 | B17: Reflux Drum | C17: 1 | D17: Collect condensate and provide reflux | E17: R = Column!B19
A18: E-06 | B18: Partial Reboiler | C18: 1 | D18: Provide boilup to column | E18: =Energy_Cost!D6 -> 411.85878
